Process Process-2:
Traceback (most recent call last):
  File "/usr/lib/python3.4/multiprocessing/process.py", line 254, in _bootstrap
    self.run()
  File "/usr/lib/python3.4/multiprocessing/process.py", line 93, in run
    self._target(*self._args, **self._kwargs)
  File "/home/pi/Downloads/registraator-master/src/esteid_data.py", line 57, in test_commit
    result = parse(get_data())
  File "/home/pi/Downloads/registraator-master/src/esteid_data.py", line 16, in get_data
    print(eidenv_raw.decode('utf-8'))
UnicodeDecodeError: 'utf-8' codec can't decode byte 0xc4 in position 14: invalid continuation byte


Process Process-2:
Traceback (most recent call last):
  File "/usr/lib/python3.4/multiprocessing/process.py", line 254, in _bootstrap
    self.run()
  File "/usr/lib/python3.4/multiprocessing/process.py", line 93, in run
    self._target(*self._args, **self._kwargs)
  File "/home/pi/Downloads/registraator-master/src/esteid_data.py", line 57, in test_commit
    result = parse(get_data())
  File "/home/pi/Downloads/registraator-master/src/esteid_data.py", line 16, in get_data
    print(eidenv_raw.encode('utf-8'))
AttributeError: 'bytes' object has no attribute 'encode'
